## Promise

### Promise 状态机

+ **`pending`**
+ **`fulfilled `/` resolved`**
+ **`rejected`**

> `Promise` 的状态是私有的，不能直接通过 `JavaScript` 检测到，也不能被代码修改
>
> 这是为了避免根据读取到的`Promise` 状态，以同步方式处理`Promise` 对象
>
> **`Promise` 故意将异步行为封装起来，从而隔离外部的同步代码**



### 解决值、拒绝理由及`Promise` 用例

#### `Promise` 用途

+  抽象地表示一个异步操作
+ `Promise` 封装的一步操作会实际生成某个值，而程序期待`Promise` 状态改变时可以访问这个值



### `Promise.resolve()`

+ `Promise.resolve()` 可以把任何值都转换为一个`Promise`

  ```js
  let p = Promise.resolve(7);
  setTimeout(console.log, 0, p === Promise.resolve(p));
  // true
  setTimeout(console.log, 0, p === Promise.resolve(Promise.resolve(p)));
  // true
  ```

+ 保留传入 `Promise` 的状态

  ```js
  let p = new Promise(() => {});
  setTimeout(console.log, 0, p);                        // Promise <pending>
  setTimeout(console.log, 0, Promise.resolve(p));   // Promise <pending>
  setTimeout(console.log, 0, p === Promise.resolve(p)); //true
  ```

+ 这个静态方法能够包装任何非期约值，包括错误对象，并将其转换为解决的`Promise`

  ```js
  let p = Promise.resolve(new Error('foo'));
  setTimeout(console.log, 0, p);
  //Promise<resolved>: Error: foo
  ```

### `Promise.reject()`

+ `Promise.reject()`会实例化一个拒绝的`Promise`并抛出一个异步错误

+ 这个错误不能通过`try/catch`捕获，而只能通过拒绝处理程序捕获

+ 这个拒绝的`Promise`的理由就是传给`Promise.reject()`的第一个参数。这个参数也会传给后续的拒绝处理程序

  ```js
  let p = Promise.reject(3);
  setTimeout(console.log, 0, p); // Promise <rejected>: 3
  p.then(null, (e) => setTimeout(console.log, 0, e)); // 3
  ```

+ 如果给它传一个`Promise`对象，则这个`Promise`会成为它返回的拒绝`Promise`的理由

  ```js
  setTimeout(console.log, 0, Promise.reject(Promise.resolve()));
  // Promise <rejected>: Promise <resolved>
  ```

  

**拒绝`Promise`**的错误并没有抛到执行同步代码的线程里，而是通过浏览器**异步消息队列**来处理的

```js
try {
  thrownewError('foo');
} catch(e) {
  console.log(e); // Error: foo
}
try {
  Promise.reject(newError('bar'));
} catch(e) {
  console.log(e);
}
//Uncaught(inpromise)Error: bar
```

**`try/catch`块并不能捕获该错误**

### `Promise.prototype.then()`

+ 为`Promise`实例添加处理程序的主要方法

+ `Promise.prototype.then()`方法返回一个新的期约实例

  + 这个新`Promise`实例基于`onResovled`处理程序的返回值构建
  + 其是通过`Promise.resolve()`包装来生成新期约
  + 如果没有提供这个处理程序，则`Promise.resolve()`就会包装上一个`Promise`解决之后的值。如果没有显式的返回语句，则`Promise.resolve()`会包装默认的返回值`undefined`

  ```js
  let p1 = Promise.resolve('foo');
  // 若调用then()时不传处理程序，则原样向后传
  let p2 = p1.then();
  setTimeout(console.log, 0, p2); // Promise <resolved>: foo
  // 这些都一样
  let p3 = p1.then(() => undefined);
  let p4 = p1.then(() => {});
  let p5 = p1.then(() => Promise.resolve());
  setTimeout(console.log, 0, p3);   // Promise <resolved>: undefined
  setTimeout(console.log, 0, p4);   // Promise <resolved>: undefined
  setTimeout(console.log, 0, p5);   // Promise <resolved>: undefined
  
  // 这些都一样
  let p6 = p1.then(() => 'bar');
  let p7 = p1.then(() => Promise.resolve('bar'));
  setTimeout(console.log, 0, p6);   // Promise <resolved>: bar
  setTimeout(console.log, 0, p7);   // Promise <resolved>: bar
  // Promise.resolve()保留返回的 promise
  let p8 = p1.then(() => new Promise(() => {}));
  let p9 = p1.then(() => Promise.reject());
  // Uncaught (in promise): undefined
  setTimeout(console.log, 0, p8);   // Promise <pending>
  setTimeout(console.log, 0, p9);   // Promise <rejected>: undefined
  ```

  **抛出异常会返回拒绝的期约**

  ```js
  ...
  let p10 = p1.then(() => { throw 'baz'; });
  // Uncaught (in promise) baz
  setTimeout(console.log, 0, p10);   // Promise <rejected> baz
  ```

  **返回错误值不会触发上面的拒绝行为，而会把错误对象包装在一个解决的`Promise`中**

  ```js
  ...
  let p11 = p1.then(() => Error('qux'));
  setTimeout(console.log, 0, p11); // Promise <resolved>: Error: qux
  ```

  

### `Promise.prototype.catch()`

`Promise.prototype.catch()`方法用于给`Promise`添加拒绝处理程序。这个方法只接收一个参数：`onRejected`处理程序

```js
let p = Promise.reject();
let onRejected = function(e) {
  setTimeout(console.log, 0, 'rejected');
};
// 这两种添加拒绝处理程序的方式是一样的：
p.then(null, onRejected);   // rejected
p.catch(onRejected);        //rejected
```

`Promise.prototype.catch()` 返回一个新的`Promise`实例

```js
let p1 = new Promise(() => {});
let p2 = p1.catch();
setTimeout(console.log, 0, p1);           // Promise <pending>
setTimeout(console.log, 0, p2);          //Promise<pending>
setTimeout(console.log, 0, p1 === p2);  //false
```



### `Promise.prototype.finally()`

`Promise.prototype.finally()`方法返回一个新的`Promise`实例

```js
let p1 = new Promise(() => {});
letp2=p1.finally();
setTimeout(console.log, 0, p1);           // Promise <pending>
setTimeout(console.log, 0, p2);          //Promise<pending>
setTimeout(console.log, 0, p1===p2);  //false
```

这个新`Promise`实例不同于`then()`或`catch()`方式返回的实例。因为`onFinally`被设计为一个状态无关的方法，所以在大多数情况下它将表现为父 `Promise` 的传递。对于**已解决状态**和**被拒绝状态**都是如此

```js
let p1 = Promise.resolve('foo');
// 这里都会原样后传
let p2 = p1.finally();
let p3 = p1.finally(() => undefined);
let p4 = p1.finally(() => {});
let p5 = p1.finally(() => Promise.resolve());
let p6 = p1.finally(() => 'bar');
let p7 = p1.finally(() => Promise.resolve('bar'));
let p8 = p1.finally(() => Error('qux'));
setTimeout(console.log, 0, p2);   // Promise <resolved>: foo
setTimeout(console.log, 0, p3);   // Promise <resolved>: foo
setTimeout(console.log, 0, p4);   // Promise <resolved>: foo
setTimeout(console.log, 0, p5);   // Promise <resolved>: foo
setTimeout(console.log, 0, p6);   // Promise <resolved>: foo
setTimeout(console.log, 0, p7);   // Promise <resolved>: foo
setTimeout(console.log, 0, p8);   // Promise <resolved>: foo
```

如果返回的是一个**待定**的`Promise`，或者`onFinally`处理程序抛出了错误（显式抛出或返回了一个拒绝`Promise`），则会返回相应的`Promise`（待定或拒绝）

```js
...
// Promise.resolve()保留返回的 Promise
let p9 = p1.finally(() => new Promise(() => {}));
let p10 = p1.finally(() => Promise.reject());
// Uncaught (in promise): undefined
setTimeout(console.log, 0, p9);   // Promise <pending>
setTimeout(console.log, 0, p10); // Promise <rejected>: undefined
let p11 = p1.finally(() => { throw 'baz'; });
// Uncaught (in promise) baz
setTimeout(console.log, 0, p11); // Promise <rejected>: baz
```



### 非重入 `Promise` 方法

当`Promise`进入落定状态时，与该状态相关的处理程序仅仅会被排期，而非立即执行

**跟在添加这个处理程序的代码之后的同步代码一定会在处理程序之前先执行**

即使 `Promise` 一开始就是与附加处理程序关联的状态，执行顺序也是这样的

```js
// 创建解决的 promise
let p = Promise.resolve();
// 添加解决处理程序
// 直觉上，这个处理程序会等 promise 一解决就执行
p.then(() => console.log('onResolved handler'));
// 同步输出，证明then()已经返回
console.log('then() returns');
// 实际的输出：
//then()returns
//onResolvedhandler
```

在一个解决`Promise`上调用`then()`会把`onResolved`处理程序**推进消息队列**。但这个处理程序在当前线程上的同步代码执行完成前不会执行

```js
let synchronousResolve;
// 创建一个期约并将解决函数保存在一个局部变量中
let p = new Promise((resolve) => {
  synchronousResolve = function() {
    console.log('1: invoking resolve()');
    resolve();
    console.log('2: resolve() returns');
  };
});
p.then(() => console.log('4: then() handler executes'));
synchronousResolve();
console.log('3: synchronousResolve() returns');
// 实际的输出：
//1: invokingresolve()
// 2: resolve()returns
// 3: synchronousResolve() returns
// 4: then() handler executes
```



**非重入**适用于`onResolved`/`onRejected`处理程序、`catch()`处理程序和finally()`处理程序

```js
let p1 = Promise.resolve();
p1.then(() => console.log('p1.then() onResolved'));
console.log('p1.then() returns');
let p2 = Promise.reject();
p2.then(null, () => console.log('p2.then() onRejected'));
console.log('p2.then() returns');
let p3 = Promise.reject();
p3.catch(() => console.log('p3.catch() onRejected'));
console.log('p3.catch() returns');
let p4 = Promise.resolve();
p4.finally(() => console.log('p4.finally() onFinally'));
console.log('p4.finally() returns');
// p1.then() returns
// p2.then() returns
// p3.catch() returns
// p4.finally() returns
//p1.then()onResolved
//p2.then()onRejected
//p3.catch()onRejected
//p4.finally()onFinally
```

#### 邻近处理程序的执行顺序

```js
let p1 = Promise.resolve();
let p2 = Promise.reject();
p1.then(() => setTimeout(console.log, 0, 1));
p1.then(() => setTimeout(console.log, 0, 2));
// 1
// 2
p2.then(null, () => setTimeout(console.log, 0, 3));
p2.then(null, () => setTimeout(console.log, 0, 4));
// 3
// 4
p2.catch(() => setTimeout(console.log, 0, 5));
p2.catch(() => setTimeout(console.log, 0, 6));
// 5
// 6
p1.finally(() => setTimeout(console.log, 0, 7));
p1.finally(() => setTimeout(console.log, 0, 8));
// 7
// 8
```

异步错误只能通过异步的`onRejected`处理程序捕获

```js
// 正确
Promise.reject(Error('foo')).catch((e) => {});
// 不正确
try {
  Promise.reject(Error('foo'));
} catch(e) {}
```



### `Promise.all()`

`Promise.all()`静态方法创建的`Promise`会在一组`Promise`全部解决之后再解决

这个静态方法接收一个可迭代对象，返回一个新`Promise`

```js
let p1 = Promise.all([
  Promise.resolve(),
  Promise.resolve()
]);
// 可迭代对象中的元素会通过Promise.resolve()转换为期约
let p2 = Promise.all([3, 4]);
// 空的可迭代对象等价于Promise.resolve()
let p3 = Promise.all([]);
// 无效的语法
let p4 = Promise.all();
// TypeError: cannot read Symbol.iterator of undefined
```

如果至少有一个包含的`Promise`待定，则合成的`Promise`也会待定。如果有一个包含的`Promise`拒绝，则合成的`Promise`也会拒绝



#### `Promise.race()`

```js
let p1 = Promise.race([
  Promise.resolve(),
  Promise.resolve()
]);
// 可迭代对象中的元素会通过Promise.resolve()转换为期约
let p2 = Promise.race([3, 4]);
// 空的可迭代对象等价于new Promise(() => {})
let p3 = Promise.race([]);
// 无效的语法
let p4 = Promise.race();
// TypeError: cannot read Symbol.iterator of undefined
```

`Promise.race(`)不会对解决或拒绝的`Promise`区别对待。无论是解决还是拒绝，只要是第一个落定的`Promise`，`Promise.race() `就会包装其解决值或拒绝理由并返回新`Promise`

```js
// 解决先发生，超时后的拒绝被忽略
let p1 = Promise.race([
  Promise.resolve(3),
  new Promise((resolve, reject) => setTimeout(reject, 1000))
]);
setTimeout(console.log, 0, p1); // Promise <resolved>: 3
// 拒绝先发生，超时后的解决被忽略
let p2 = Promise.race([
  Promise.reject(4),
  new Promise((resolve, reject) => setTimeout(resolve, 1000))
]);
setTimeout(console.log, 0, p2); // Promise <rejected>: 4
// 迭代顺序决定了落定顺序
let p3 = Promise.race([
  Promise.resolve(5),
  Promise.resolve(6),
  Promise.resolve(7)
]);
setTimeout(console.log, 0, p3); // Promise <resolved>: 5
```

###  串行`Promise` 合成

```js
function addTwo(x) {return x + 2; }
function addThree(x) {return x + 3; }
function addFive(x) {return x + 5; }
functioncompose(...fns){
  return(x)=>fns.reduce((promise, fn)=>promise.then(fn), Promise.resolve(x))
}
let addTen = compose(addTwo, addThree, addFive);
addTen(8).then(console.log); // 18 
```



### `Promise` 扩展

+ `Promise` 取消

  ```js
  class CancelToken {
    constructor(cancelFn) {
      this.promise = new Promise((resolve, reject) => {
        cancelFn(resolve);
      });
    }
  }
  ```

  ```html
  <body>
    <button id="start">Start</button>
    <button id="cancel">Cancel</button>
    <script>
      class CancelToken {
        constructor(cancelFn) {
          this.promise = new Promise((resolve, reject) => {
            cancelFn(() => {
              setTimeout(console.log, 0, "delay cancelled");
              resolve();
            });
          });
        }
      }
      const startButton = document.querySelector('#start');
      const cancelButton = document.querySelector('#cancel');
      function cancellableDelayedResolve(delay) {
        setTimeout(console.log, 0, "set delay");
        return new Promise((resolve, reject) => {
          const id = setTimeout((() => {
            setTimeout(console.log, 0, "delayed resolve");
            resolve();
          }), delay);
          const cancelToken = new CancelToken((cancelCallback) => {
            cancelButton.addEventListener("click", cancelCallback);
          })
          cancelToken.promise.then(() => clearTimeout(id));
        });
      }
      startButton.addEventListener("click", () => cancellableDelayedResolve(1000));
    </script>
  </body>
  ```

+ `Promise` 进度通知

  + `ES6`不支持取消`Promise`和**进度通知**，一个主要原因就是这样会导致`Promise`连锁和`Promise`合成过度复杂化

## 异步函数

`ES8`的`async ` / `await`旨在解决利用异步结构组织代码的问题

```js
async function foo() {}
let bar = async function() {};
let baz = async () => {};
class Qux {
  async qux() {}
}
```

```js
async function foo() {
  console.log(1);
}
foo();
console.log(2);
// 1
// 2
```

```js
async function foo() {
  console.log(1);
  return3;
}
// 给返回的期约添加一个解决处理程序
foo().then(console.log);
console.log(2);
// 1
// 2
// 3
```

等待会抛出错误的同步操作，会返回拒绝的`Promise`

```js
async function foo() {
  console.log(1);
  await(() => { throw 3; })();
}
// 给返回的期约添加一个拒绝处理程序
foo().catch(console.log);
console.log(2);
// 1
// 2
// 3
```

单独的`Promise.reject()`不会被异步函数捕获

```js
async function foo() {
  console.log(1);
  Promise.reject(3);
}
// Attach a rejected handler to the returned promise
foo().catch(console.log);
console.log(2);
// 1
// 2
//Uncaught(inpromise): 3
```

对拒绝的 `Promise` 使用 `await` 则会释放错误值（将拒绝`Promise`返回）

```js
async function foo() {
  console.log(1);
  await Promise.reject(3);
  console.log(4); // 这行代码不会执行
}
// 给返回的期约添加一个拒绝处理程序
foo().catch(console.log);
console.log(2);
// 1
// 2
// 3
```

### 停止和恢复执行

```js
async function foo() {
  console.log(2);
  console.log(await Promise.resolve(8));
  console.log(9);
}
async function bar() {
  console.log(4);
  console.log(await 6);
  console.log(7);
}
console.log(1);
foo();
console.log(3);
bar();
console.log(5);
// 1
// 2
// 3
// 4
// 5
// 6
// 7
// 8
// 9
```

## 异步函数策略

```js
async function sleep(delay) {
  return new Promise((resolve) => setTimeout(resolve, delay));
}
async function foo() {
  const t0 = Date.now();
  awaitsleep(1500);// 暂停约1500 毫秒
  console.log(Date.now() - t0);
}
foo();
// 1502
```

```js
async function randomDelay(id) {
  // 延迟0~1000 毫秒
  const delay = Math.random() ＊ 1000;
  return new Promise((resolve) => setTimeout(() => {
    console.log(`${id} finished`);
    resolve(id);
  }, delay));
}
async function foo() {
  const t0 = Date.now();
  const promises = Array(5).fill(null).map((_, i) => randomDelay(i));
  for (const p of promises) {
    console.log(`awaited ${await p}`);
  }
  console.log(`${Date.now() - t0}ms elapsed`);
}
foo();
// 1 finished
// 2 finished
// 4 finished
// 3 finished
// 0 finished
// awaited 0
// awaited 1
// awaited 2
// awaited 3
// awaited 4
// 645ms elapsed
```



```js
async function addTwo(x) {return x + 2; }
async function addThree(x) {return x + 3; }
async function addFive(x) {return x + 5; }
async function addTen(x) {
  for (const fn of [addTwo, addThree, addFive]) {
    x = await fn(x);
  }
  return x;
}
addTen(9).then(console.log); // 19
```

### 栈追踪和内存管理

```js
function fooPromiseExecutor(resolve, reject) {
  setTimeout(reject, 1000, 'bar');
}
function foo() {
  new Promise(fooPromiseExecutor);
}
foo();
// Uncaught (in promise) bar
//    setTimeout
//    setTimeout (async)
//   fooPromiseExecutor
//   foo
```

```js
function fooPromiseExecutor(resolve, reject) {
  setTimeout(reject, 1000, 'bar');
}
asyncfunction foo() {
  awaitnew Promise(fooPromiseExecutor);
}
foo();
// Uncaught (in promise) bar
//   foo
//   asyncfunction(async)
//   foo
```

